Workbook

Sheet Employees
A1: بيانات الموظفين - أبريل 2025
A2: شهر العمل: أبريل | أيام العمل: 27 يوم
A3: كود الموظف | B3: اسم الموظف | C3: الوظيفة | D3: المرتب الشهري | E3: أيام العمل | F3: ساعات العمل اليومية | G3: ميعاد الحضور | H3: ميعاد الانصراف | I3: أجر اليوم | J3: أجر الساعة
A4: EMP-001 | B4: احمد خالد | C4: مدير مبيعات | D4: 10000 | E4: 27 | F4: 10 | G4: 0.5 | H4: 0.91666667 | I4: =D4/27 -> 370.37037 | J4: =I4/F4 -> 37.037037
A5: EMP-002 | B5: هشام عادل | C5: مدير مبيعات | D5: 9000 | E5: 27 | F5: 9 | G5: 0.41666667 | H5: 0.79166667 | I5: =D5/27 -> 333.33333 | J5: =I5/F5 -> 37.037037
A6: EMP-003 | B6: احمد الشاذلى | C6: مبيعات | D6: 7000 | E6: 27 | F6: 9 | G6: 0.41666667 | H6: 0.79166667 | I6: =D6/27 -> 259.25926 | J6: =I6/F6 -> 28.806584
A7: EMP-004 | B7: يوسف احمد | C7: مبيعات | D7: 7000 | E7: 27 | F7: 12 | G7: 0.41666667 | H7: 0.91666667 | I7: =D7/27 -> 259.25926 | J7: =I7/F7 -> 21.604938
A8: EMP-005 | B8: محمد السيد | C8: مبيعات | D8: 7000 | E8: 27 | F8: 12 | G8: 0.41666667 | H8: 0.91666667 | I8: =D8/27 -> 259.25926 | J8: =I8/F8 -> 21.604938
A9: EMP-006 | B9: يحي طارق | C9: مبيعات | D9: 7000 | E9: 27 | F9: 12 | G9: 0.41666667 | H9: 0.91666667 | I9: =D9/27 -> 259.25926 | J9: =I9/F9 -> 21.604938
A10: EMP-007 | B10: عابدين محمد | C10: مبيعات | D10: 7000 | E10: 27 | F10: 12 | G10: 0.41666667 | H10: 0.91666667 | I10: =D10/27 -> 259.25926 | J10: =I10/F10 -> 21.604938
A11: EMP-008 | B11: احمد رمصان | C11: مبيعات | D11: 7000 | E11: 27 | F11: 10 | G11: 0.5 | H11: 0.91666667 | I11: =D11/27 -> 259.25926 | J11: =I11/F11 -> 25.925926
A12: EMP-009 | B12: هشام اشرف | C12: مبيعات | D12: 7000 | E12: 27 | F12: 12 | G12: 0.41666667 | H12: 0.91666667 | I12: =D12/27 -> 259.25926 | J12: =I12/F12 -> 21.604938
A13: EMP-010 | B13: محمود اسماعيل | C13: مبيعات | D13: 7000 | E13: 27 | F13: 7 | G13: 0.625 | H13: 0.91666667 | I13: =D13/27 -> 259.25926 | J13: =I13/F13 -> 37.037037
A14: EMP-011 | B14: ابراهيم خليفة | C14: مبيعات | D14: 7000 | E14: 27 | F14: 12 | G14: 0.41666667 | H14: 0.91666667 | I14: =D14/27 -> 259.25926 | J14: =I14/F14 -> 21.604938
A15: EMP-012 | B15: طارق سعد | C15: مبيعات | D15: 7000 | E15: 27 | F15: 12 | G15: 09:00 AM | H15: 05:00 PM | I15: =D15/27 -> 259.25926 | J15: =I15/F15 -> 21.604938
A16: EMP-013 | B16: مؤمن جاد | C16: مبيعات | D16: 7000 | E16: 27 | F16: 10 | G16: 09:00 AM | H16: 05:00 PM | I16: =D16/27 -> 259.25926 | J16: =I16/F16 -> 25.925926
A17: EMP-014 | B17: محمد حسين | C17: حسابات | D17: 11000 | E17: 27 | F17: 10 | G17: 0.5 | H17: 0.91666667 | I17: =D17/27 -> 407.40741 | J17: =I17/F17 -> 40.740741
A18: EMP-015 | B18: معتز شوقى | C18: حسابات | D18: 11000 | E18: 27 | F18: 10 | G18: 0.5 | H18: 0.91666667 | I18: =D18/27 -> 407.40741 | J18: =I18/F18 -> 40.740741
A19: EMP-016 | B19: احمد عزت | C19: حسابات | D19: 9000 | E19: 27 | F19: 9 | G19: 0.5 | H19: 0.875 | I19: =D19/27 -> 333.33333 | J19: =I19/F19 -> 37.037037
A20: EMP-017 | B20: احمد جمعه | C20: حسابات | D20: 9000 | E20: 27 | F20: 12 | G20: 0.41666667 | H20: 0.91666667 | I20: =D20/27 -> 333.33333 | J20: =I20/F20 -> 27.777778
A21: EMP-018 | B21: محمد سمير | C21: حسابات | D21: 9000 | E21: 27 | F21: 12 | G21: 0.41666667 | H21: 0.91666667 | I21: =D21/27 -> 333.33333 | J21: =I21/F21 -> 27.777778
A22: EMP-019 | B22: احمد سمير | C22: حسابات | D22: 7000 | E22: 27 | F22: 12 | G22: 0.41666667 | H22: 0.91666667 | I22: =D22/27 -> 259.25926 | J22: =I22/F22 -> 21.604938
A23: EMP-020 | B23: محمد عبد الكريم | C23: حسابات | D23: 7000 | E23: 27 | F23: 12 | G23: 0.41666667 | H23: 0.91666667 | I23: =D23/27 -> 259.25926 | J23: =I23/F23 -> 21.604938
A24: EMP-021 | B24: عبدالرحمن على | C24: حسابات | D24: 7000 | E24: 27 | F24: 12 | G24: 0.41666667 | H24: 0.91666667 | I24: =D24/27 -> 259.25926 | J24: =I24/F24 -> 21.604938
A25: EMP-022 | B25: مصطفى شريف | C25: اداره | D25: 12000 | E25: 27 | F25: 12 | G25: 0.41666667 | H25: 0.91666667 | I25: =D25/27 -> 444.44444 | J25: =I25/F25 -> 37.037037
A26: EMP-023 | B26: احمد اشرف | C26: اداره | D26: 12000 | E26: 27 | F26: 12 | G26: 0.41666667 | H26: 0.91666667 | I26: =D26/27 -> 444.44444 | J26: =I26/F26 -> 37.037037
A27: EMP-024 | B27: منى ناصر | C27: تسويق | D27: 10500 | E27: 27 | F27: 12 | G27: 0.41666667 | H27: 0.91666667 | I27: =D27/27 -> 388.88889 | J27: =I27/F27 -> 32.407407
A28: EMP-025 | B28: مريم فتح الله | C28: تسويق | D28: 10500 | E28: 27 | F28: 12 | G28: 0.41666667 | H28: 0.91666667 | I28: =D28/27 -> 388.88889 | J28: =I28/F28 -> 32.407407
... A33: EMP-030 | B33: محمد طارق | C33: تسويق | D33: 9500 | E33: 27 | F33: 12 | G33: 0.41666667 | H33: 0.91666667 | I33: =D33/27 -> 351.85185 | J33: =I33/F33 -> 29.320988
A34: EMP-031 | B34: انس انور | C34: اداره | D34: 12000 | E34: 27 | F34: 9 | G34: 09:00 AM | H34: 05:00 PM | I34: =D34/27 -> 444.44444 | J34: =I34/F34 -> 49.382716
A35: EMP-032 | B35: مراون عادل | C35: اداره | D35: 12000 | E35: 27 | F35: 12 | G35: 09:00 AM | H35: 05:00 PM | I35: =D35/27 -> 444.44444 | J35: =I35/F35 -> 37.037037
A36: EMP-033 | B36: سعد محمد | C36: اداره | D36: 12000 | E36: 27 | F36: 8 | G36: 0.41666667 | H36: 0.75 | I36: =D36/27 -> 444.44444 | J36: =I36/F36 -> 55.555556

Sheet Attendance
A1: سجل الحضور والانصراف - أبريل 2025
A2: التاريخ | B2: اليوم | C2: كود الموظف | D2: اسم الموظف | E2: وقت الحضور | F2: وقت الانصراف | G2: حالة اليوم | H2: C/IN | I2: C/OUT | J2: حضور مبكر | K2: اجر الحضور المبكر | L2: ساعات التأخير | M2: خصم التأخير | N2: ساعات الأوفر تايم | O2: أجر الأوفر تايم | P2: خصم الغياب
A3: 📌 قاعدة التأخير: سماح 30 دقيقة، بعدها يُحسب ساعة كاملة | قاعدة الأوفر تايم: أول 30 دقيقة لا تُحسب، بعدها ساعة كاملة
A4: 01/04/2025 | B4: الاربعاء | C4: EMP-001 | D4: =VLOOKUP(C4,Employees!A:J,2,0) -> احمد خالد | E4: 0.45833333 | F4: 0.875 | G4: حضور | H4: =E4 -> 0.45833333 | I4: =F4 -> 0.875 | J4: =IF(OR(H4="",G4="غياب",G4="إجازة أسبوعية"),0, IF(H4>=E4-TIME(0,20,0),0, IF(H4>=E4-TIME(0,30,0),30,(E4-H4)*1440))) -> 0 | K4: =(J4/60)*VLOOKUP(C4,Employees!1:1048576,10,0)*1.5 -> 0 | L4: =IF(OR(H4="",G4="غياب",G4="إجازة أسبوعية"),0, IF(H4<=E4+TIME(0,30,0),0, 30+((H4-(E4+TIME(0,30,0)))*1440))) -> 0 | M4: =(L4/60)*VLOOKUP(C4,Employees!A:J,10,0)*2 -> 0 | N4: =IF(OR(I4="",G4="غياب",G4="إجازة أسبوعية",I4<=F4),0, IF(MOD(I4-F4,1)<=TIME(0,25,0),0,MAX(0,(I4-F4)*1440))) -> 0 | O4: =(N4/60)*VLOOKUP(C4,Employees!A:J,10,0)*1.5 -> 0 | P4: =IF(G4="غياب",VLOOKUP(C4,Employees!$A$3:$J$36,9,FALSE()),0) -> 0
A5: 02/04/2025 | B5: الخميس | C5: EMP-001 | D5: =VLOOKUP(C5,Employees!A:J,2,0) -> احمد خالد | E5: 0.45833333 | F5: 0.875 | G5: حضور | H5: =E5 -> 0.45833333 | I5: =F5 -> 0.875 | J5: =IF(OR(H5="",G5="غياب",G5="إجازة أسبوعية"),0, IF(H5>=E5-TIME(0,20,0),0, IF(H5>=E5-TIME(0,30,0),30,(E5-H5)*1440))) -> 0 | K5: =(J5/60)*VLOOKUP(C5,Employees!A:J,10,0)*1.5 -> 0 | L5: =IF(OR(H5="",G5="غياب",G5="إجازة أسبوعية"),0, IF(H5<=E5+TIME(0,30,0),0, 30+((H5-(E5+TIME(0,30,0)))*1440))) -> 0 | M5: =(L5/60)*VLOOKUP(C5,Employees!A:J,10,0)*2 -> 0 | N5: =IF(OR(I5="",G5="غياب",G5="إجازة أسبوعية",I5<=F5),0, IF(MOD(I5-F5,1)<=TIME(0,25,0),0,MAX(0,(I5-F5)*1440))) -> 0 | O5: =(N5/60)*VLOOKUP(C5,Employees!A:J,10,0)*1.5 -> 0 | P5: =IF(G5="غياب",VLOOKUP(C5,Employees!$A$3:$J$36,9,FALSE()),0) -> 0
A6: 03/04/2025 | B6: الجمعه | C6: EMP-001 | D6: =VLOOKUP(C6,Employees!A:J,2,0) -> احمد خالد | E6: 0.45833333 | F6: 0.875 | G6: حضور | H6: =E6 -> 0.45833333 | I6: =F6 -> 0.875 | J6: =IF(OR(H6="",G6="غياب",G6="إجازة أسبوعية"),0, IF(H6>=E6-TIME(0,20,0),0, IF(H6>=E6-TIME(0,30,0),30,(E6-H6)*1440))) -> 0 | K6: =(J6/60)*VLOOKUP(C6,Employees!A:J,10,0)*1.5 -> 0 | L6: =IF(OR(H6="",G6="غياب",G6="إجازة أسبوعية"),0, IF(H6<=E6+TIME(0,30,0),0, 30+((H6-(E6+TIME(0,30,0)))*1440))) -> 0 | M6: =(L6/60)*VLOOKUP(C6,Employees!A:J,10,0)*2 -> 0 | N6: =IF(OR(I6="",G6="غياب",G6="إجازة أسبوعية",I6<=F6),0, IF(MOD(I6-F6,1)<=TIME(0,25,0),0,MAX(0,(I6-F6)*1440))) -> 0 | O6: =(N6/60)*VLOOKUP(C6,Employees!A:J,10,0)*1.5 -> 0 | P6: =IF(G6="غياب",VLOOKUP(C6,Employees!$A$3:$J$36,9,FALSE()),0) -> 0
A7: 04/04/2025 | B7: السبت | C7: EMP-001 | D7: =VLOOKUP(C7,Employees!A:J,2,0) -> احمد خالد | E7: 0.45833333 | F7: 0.875 | G7: حضور | H7: =E7 -> 0.45833333 | I7: =F7 -> 0.875 | J7: =IF(OR(H7="",G7="غياب",G7="إجازة أسبوعية"),0, IF(H7>=E7-TIME(0,20,0),0, IF(H7>=E7-TIME(0,30,0),30,(E7-H7)*1440))) -> 0 | K7: =(J7/60)*VLOOKUP(C7,Employees!A:J,10,0)*1.5 -> 0 | L7: =IF(OR(H7="",G7="غياب",G7="إجازة أسبوعية"),0, IF(H7<=E7+TIME(0,30,0),0, 30+((H7-(E7+TIME(0,30,0)))*1440))) -> 0 | M7: =(L7/60)*VLOOKUP(C7,Employees!A:J,10,0)*2 -> 0 | N7: =IF(OR(I7="",G7="غياب",G7="إجازة أسبوعية",I7<=F7),0, IF(MOD(I7-F7,1)<=TIME(0,25,0),0,MAX(0,(I7-F7)*1440))) -> 0 | O7: =(N7/60)*VLOOKUP(C7,Employees!A:J,10,0)*1.5 -> 0 | P7: =IF(G7="غياب",VLOOKUP(C7,Employees!$A$3:$J$36,9,FALSE()),0) -> 0
A8: 05/04/2025 | B8: الاحد | C8: EMP-001 | D8: =VLOOKUP(C8,Employees!A:J,2,0) -> احمد خالد | E8: _ | F8: _ | G8: اجازة اسبوعية | H8: _ | I8: _ | J8: _ | K8: _ | L8: _ | M8: _ | N8: _ | O8: _ | P8: =IF(G8="غياب",VLOOKUP(C8,Employees!$A$3:$J$36,9,FALSE()),0) -> 0
A9: 06/04/2025 | B9: الاثنين | C9: EMP-001 | D9: =VLOOKUP(C9,Employees!A:J,2,0) -> احمد خالد | E9: 0.45833333 | F9: 0.875 | G9: حضور | H9: =E9 -> 0.45833333 | I9: =F9 -> 0.875 | J9: =IF(OR(H9="",G9="غياب",G9="إجازة أسبوعية"),0, IF(H9>=E9-TIME(0,20,0),0, IF(H9>=E9-TIME(0,30,0),30,(E9-H9)*1440))) -> 0 | K9: =(J9/60)*VLOOKUP(C9,Employees!A:J,10,0)*1.5 -> 0 | L9: =IF(OR(H9="",G9="غياب",G9="إجازة أسبوعية"),0, IF(H9<=E9+TIME(0,30,0),0, 30+((H9-(E9+TIME(0,30,0)))*1440))) -> 0 | M9: =(L9/60)*VLOOKUP(C9,Employees!A:J,10,0)*2 -> 0 | N9: =IF(OR(I9="",G9="غياب",G9="إجازة أسبوعية",I9<=F9),0, IF(MOD(I9-F9,1)<=TIME(0,25,0),0,MAX(0,(I9-F9)*1440))) -> 0 | O9: =(N9/60)*VLOOKUP(C9,Employees!A:J,10,0)*1.5 -> 0 | P9: =IF(G9="غياب",VLOOKUP(C9,Employees!$A$3:$J$36,9,FALSE()),0) -> 0
A10: 07/04/2025 | B10: الثلاثاء | C10: EMP-001 | D10: =VLOOKUP(C10,Employees!A:J,2,0) -> احمد خالد | E10: 0.45833333 | F10: 0.875 | G10: حضور | H10: =E10 -> 0.45833333 | I10: =F10 -> 0.875 | J10: =IF(OR(H10="",G10="غياب",G10="إجازة أسبوعية"),0, IF(H10>=E10-TIME(0,20,0),0, IF(H10>=E10-TIME(0,30,0),30,(E10-H10)*1440))) -> 0 | K10: =(J10/60)*VLOOKUP(C10,Employees!A:J,10,0)*1.5 -> 0 | L10: =IF(OR(H10="",G10="غياب",G10="إجازة أسبوعية"),0, IF(H10<=E10+TIME(0,30,0),0, 30+((H10-(E10+TIME(0,30,0)))*1440))) -> 0 | M10: =(L10/60)*VLOOKUP(C10,Employees!A:J,10,0)*2 -> 0 | N10: =IF(OR(I10="",G10="غياب",G10="إجازة أسبوعية",I10<=F10),0, IF(MOD(I10-F10,1)<=TIME(0,25,0),0,MAX(0,(I10-F10)*1440))) -> 0 | O10: =(N10/60)*VLOOKUP(C10,Employees!A:J,10,0)*1.5 -> 0 | P10: =IF(G10="غياب",VLOOKUP(C10,Employees!$A$3:$J$36,9,FALSE()),0) -> 0
A11: 08/04/2025 | B11: الاربعاء | C11: EMP-001 | D11: =VLOOKUP(C11,Employees!A:J,2,0) -> احمد خالد | E11: 0.45833333 | F11: 0.875 | G11: حضور | H11: =E11 -> 0.45833333 | I11: =F11 -> 0.875 | J11: =IF(OR(H11="",G11="غياب",G11="إجازة أسبوعية"),0, IF(H11>=E11-TIME(0,20,0),0, IF(H11>=E11-TIME(0,30,0),30,(E11-H11)*1440))) -> 0 | K11: =(J11/60)*VLOOKUP(C11,Employees!A:J,10,0)*1.5 -> 0 | L11: =IF(OR(H11="",G11="غياب",G11="إجازة أسبوعية"),0, IF(H11<=E11+TIME(0,30,0),0, 30+((H11-(E11+TIME(0,30,0)))*1440))) -> 0 | M11: =(L11/60)*VLOOKUP(C11,Employees!A:J,10,0)*2 -> 0 | N11: =IF(OR(I11="",G11="غياب",G11="إجازة أسبوعية",I11<=F11),0, IF(MOD(I11-F11,1)<=TIME(0,25,0),0,MAX(0,(I11-F11)*1440))) -> 0 | O11: =(N11/60)*VLOOKUP(C11,Employees!A:J,10,0)*1.5 -> 0 | P11: =IF(G11="غياب",VLOOKUP(C11,Employees!$A$3:$J$36,9,FALSE()),0) -> 0
A12: 09/04/2025 | B12: الخميس | C12: EMP-001 | D12: =VLOOKUP(C12,Employees!A:J,2,0) -> احمد خالد | E12: 0.45833333 | F12: 0.875 | G12: حضور | H12: =E12 -> 0.45833333 | I12: =F12 -> 0.875 | J12: =IF(OR(H12="",G12="غياب",G12="إجازة أسبوعية"),0, IF(H12>=E12-TIME(0,20,0),0, IF(H12>=E12-TIME(0,30,0),30,(E12-H12)*1440))) -> 0 | K12: =(J12/60)*VLOOKUP(C12,Employees!A:J,10,0)*1.5 -> 0 | L12: =IF(OR(H12="",G12="غياب",G12="إجازة أسبوعية"),0, IF(H12<=E12+TIME(0,30,0),0, 30+((H12-(E12+TIME(0,30,0)))*1440))) -> 0 | M12: =(L12/60)*VLOOKUP(C12,Employees!A:J,10,0)*2 -> 0 | N12: =IF(OR(I12="",G12="غياب",G12="إجازة أسبوعية",I12<=F12),0, IF(MOD(I12-F12,1)<=TIME(0,25,0),0,MAX(0,(I12-F12)*1440))) -> 0 | O12: =(N12/60)*VLOOKUP(C12,Employees!A:J,10,0)*1.5 -> 0 | P12: =IF(G12="غياب",VLOOKUP(C12,Employees!$A$3:$J$36,9,FALSE()),0) -> 0
A13: 10/04/2025 | B13: الجمعه | C13: EMP-001 | D13: =VLOOKUP(C13,Employees!A:J,2,0) -> احمد خالد | E13: 0.5 | F13: 0.875 | G13: حضور | H13: =E13 -> 0.5 | I13: =F13 -> 0.875 | J13: =IF(OR(H13="",G13="غياب",G13="إجازة أسبوعية"),0, IF(H13>=E13-TIME(0,20,0),0, IF(H13>=E13-TIME(0,30,0),30,(E13-H13)*1440))) -> 0 | K13: =(J13/60)*VLOOKUP(C13,Employees!A:J,10,0)*1.5 -> 0 | L13: =IF(OR(H13="",G13="غياب",G13="إجازة أسبوعية"),0, IF(H13<=E13+TIME(0,30,0),0, 30+((H13-(E13+TIME(0,30,0)))*1440))) -> 0 | M13: =(L13/60)*VLOOKUP(C13,Employees!A:J,10,0)*2 -> 0 | N13: =IF(OR(I13="",G13="غياب",G13="إجازة أسبوعية",I13<=F13),0, IF(MOD(I13-F13,1)<=TIME(0,25,0),0,MAX(0,(I13-F13)*1440))) -> 0 | O13: =(N13/60)*VLOOKUP(C13,Employees!A:J,10,0)*1.5 -> 0 | P13: =IF(G13="غياب",VLOOKUP(C13,Employees!$A$3:$J$36,9,FALSE()),0) -> 0
A14: 11/04/2025 | B14: السبت | C14: EMP-001 | D14: =VLOOKUP(C14,Employees!A:J,2,0) -> احمد خالد | E14: 0.5 | F14: 0.91666667 | G14: حضور | H14: =E14 -> 0.5 | I14: =F14 -> 0.91666667 | J14: =IF(OR(H14="",G14="غياب",G14="إجازة أسبوعية"),0, IF(H14>=E14-TIME(0,20,0),0, IF(H14>=E14-TIME(0,30,0),30,(E14-H14)*1440))) -> 0 | K14: =(J14/60)*VLOOKUP(C14,Employees!A:J,10,0)*1.5 -> 0 | L14: =IF(OR(H14="",G14="غياب",G14="إجازة أسبوعية"),0, IF(H14<=E14+TIME(0,30,0),0, 30+((H14-(E14+TIME(0,30,0)))*1440))) -> 0 | M14: =(L14/60)*VLOOKUP(C14,Employees!A:J,10,0)*2 -> 0 | N14: =IF(OR(I14="",G14="غياب",G14="إجازة أسبوعية",I14<=F14),0, IF(MOD(I14-F14,1)<=TIME(0,25,0),0,MAX(0,(I14-F14)*1440))) -> 0 | O14: =(N14/60)*VLOOKUP(C14,Employees!A:J,10,0)*1.5 -> 0 | P14: =IF(G14="غياب",VLOOKUP(C14,Employees!$A$3:$J$36,9,FALSE()),0) -> 0
A15: 12/04/2025 | B15: الاحد | C15: EMP-001 | D15: =VLOOKUP(C15,Employees!A:J,2,0) -> احمد خالد | E15: _ | F15: _ | G15: اجازة اسبوعية | H15: _ | I15: _ | J15: _ | K15: _ | L15: _ | M15: _ | N15: _ | O15: _ | P15: =IF(G15="غياب",VLOOKUP(C15,Employees!$A$3:$J$36,9,FALSE()),0) -> 0
A16: 13/04/2025 | B16: الاثنين | C16: EMP-001 | D16: =VLOOKUP(C16,Employees!A:J,2,0) -> احمد خالد | E16: _ | F16: _ | G16: اجازة اسبوعية | H16: _ | I16: _ | J16: _ | K16: _ | L16: _ | M16: _ | N16: _ | O16: _ | P16: =IF(G16="غياب",VLOOKUP(C16,Employees!$A$3:$J$36,9,FALSE()),0) -> 0
A17: 14/04/2025 | B17: الثلاثاء | C17: EMP-001 | D17: =VLOOKUP(C17,Employees!A:J,2,0) -> احمد خالد | E17: 0.5 | F17: 0.91666667 | G17: حضور | H17: =E17 -> 0.5 | I17: =F17 -> 0.91666667 | J17: =IF(OR(H17="",G17="غياب",G17="إجازة أسبوعية"),0, IF(H17>=E17-TIME(0,20,0),0, IF(H17>=E17-TIME(0,30,0),30,(E17-H17)*1440))) -> 0 | K17: =(J17/60)*VLOOKUP(C17,Employees!A:J,10,0)*1.5 -> 0 | L17: =IF(OR(H17="",G17="غياب",G17="إجازة أسبوعية"),0, IF(H17<=E17+TIME(0,30,0),0, 30+((H17-(E17+TIME(0,30,0)))*1440))) -> 0 | M17: =(L17/60)*VLOOKUP(C17,Employees!A:J,10,0)*2 -> 0 | N17: =IF(OR(I17="",G17="غياب",G17="إجازة أسبوعية",I17<=F17),0, IF(MOD(I17-F17,1)<=TIME(0,25,0),0,MAX(0,(I17-F17)*1440))) -> 0 | O17: =(N17/60)*VLOOKUP(C17,Employees!A:J,10,0)*1.5 -> 0 | P17: =IF(G17="غياب",VLOOKUP(C17,Employees!$A$3:$J$36,9,FALSE()),0) -> 0
A18: 15/04/2025 | B18: الاربعاء | C18: EMP-001 | D18: =VLOOKUP(C18,Employees!A:J,2,0) -> احمد خالد | E18: 0.5 | F18: 0.91666667 | G18: حضور | H18: _ | I18: _ | J18: =IF(OR(G18="غياب",G18="إجازة أسبوعية"),0, IF(H18>=E18-TIME(0,20,0),0, IF(H18>=E18-TIME(0,30,0),30,(E18-H18)*1440))) -> 0 | K18: =(J18/60)*VLOOKUP(C18,Employees!A:J,10,0)*1.5 -> 0 | L18: _ | M18: _ | N18: _ | O18: _ | P18: =IF(G18="غياب",VLOOKUP(C18,Employees!$A$3:$J$36,9,FALSE()),0) -> 0
A19: 16/04/2025 | B19: الخميس | C19: EMP-001 | D19: =VLOOKUP(C19,Employees!A:J,2,0) -> احمد خالد | E19: 0.5 | F19: 0.91666667 | G19: حضور | H19: =E19 -> 0.5 | I19: =F19 -> 0.91666667 | J19: =IF(OR(H19="",G19="غياب",G19="إجازة أسبوعية"),0, IF(H19>=E19-TIME(0,20,0),0, IF(H19>=E19-TIME(0,30,0),30,(E19-H19)*1440))) -> 0 | K19: =(J19/60)*VLOOKUP(C19,Employees!A:J,10,0)*1.5 -> 0 | L19: =IF(OR(H19="",G19="غياب",G19="إجازة أسبوعية"),0, IF(H19<=E19+TIME(0,30,0),0, 30+((H19-(E19+TIME(0,30,0)))*1440))) -> 0 | M19: =(L19/60)*VLOOKUP(C19,Employees!A:J,10,0)*2 -> 0 | N19: =IF(OR(I19="",G19="غياب",G19="إجازة أسبوعية",I19<=F19),0, IF(MOD(I19-F19,1)<=TIME(0,25,0),0,MAX(0,(I19-F19)*1440))) -> 0 | O19: =(N19/60)*VLOOKUP(C19,Employees!A:J,10,0)*1.5 -> 0 | P19: =IF(G19="غياب",VLOOKUP(C19,Employees!$A$3:$J$36,9,FALSE()),0) -> 0
A20: 17/04/2025 | B20: الجمعه | C20: EMP-001 | D20: =VLOOKUP(C20,Employees!A:J,2,0) -> احمد خالد | E20: 0.5 | F20: 0.91666667 | G20: حضور | H20: =E20 -> 0.5 | I20: =F20 -> 0.91666667 | J20: =IF(OR(H20="",G20="غياب",G20="إجازة أسبوعية"),0, IF(H20>=E20-TIME(0,20,0),0, IF(H20>=E20-TIME(0,30,0),30,(E20-H20)*1440))) -> 0 | K20: =(J20/60)*VLOOKUP(C20,Employees!A:J,10,0)*1.5 -> 0 | L20: =IF(OR(H20="",G20="غياب",G20="إجازة أسبوعية"),0, IF(H20<=E20+TIME(0,30,0),0, 30+((H20-(E20+TIME(0,30,0)))*1440))) -> 0 | M20: =(L20/60)*VLOOKUP(C20,Employees!A:J,10,0)*2 -> 0 | N20: =IF(OR(I20="",G20="غياب",G20="إجازة أسبوعية",I20<=F20),0, IF(MOD(I20-F20,1)<=TIME(0,25,0),0,MAX(0,(I20-F20)*1440))) -> 0 | O20: =(N20/60)*VLOOKUP(C20,Employees!A:J,10,0)*1.5 -> 0 | P20: =IF(G20="غياب",VLOOKUP(C20,Employees!$A$3:$J$36,9,FALSE()),0) -> 0
A21: 18/04/2025 | B21: السبت | C21: EMP-001 | D21: =VLOOKUP(C21,Employees!A:J,2,0) -> احمد خالد | E21: 0.5 | F21: 0.91666667 | G21: حضور | H21: =E21 -> 0.5 | I21: =F21 -> 0.91666667 | J21: =IF(OR(H21="",G21="غياب",G21="إجازة أسبوعية"),0, IF(H21>=E21-TIME(0,20,0),0, IF(H21>=E21-TIME(0,30,0),30,(E21-H21)*1440))) -> 0 | K21: =(J21/60)*VLOOKUP(C21,Employees!A:J,10,0)*1.5 -> 0 | L21: =IF(OR(H21="",G21="غياب",G21="إجازة أسبوعية"),0, IF(H21<=E21+TIME(0,30,0),0, 30+((H21-(E21+TIME(0,30,0)))*1440))) -> 0 | M21: =(L21/60)*VLOOKUP(C21,Employees!A:J,10,0)*2 -> 0 | N21: =IF(OR(I21="",G21="غياب",G21="إجازة أسبوعية",I21<=F21),0, IF(MOD(I21-F21,1)<=TIME(0,25,0),0,MAX(0,(I21-F21)*1440))) -> 0 | O21: =(N21/60)*VLOOKUP(C21,Employees!A:J,10,0)*1.5 -> 0 | P21: =IF(G21="غياب",VLOOKUP(C21,Employees!$A$3:$J$36,9,FALSE()),0) -> 0
A22: 19/04/2025 | B22: الاحد | C22: EMP-001 | D22: =VLOOKUP(C22,Employees!A:J,2,0) -> احمد خالد | E22: _ | F22: _ | G22: اجازة اسبوعية | H22: _ | I22: _ | J22: _ | K22: _ | L22: _ | M22: _ | N22: _ | O22: _ | P22: =IF(G22="غياب",VLOOKUP(C22,Employees!$A$3:$J$36,9,FALSE()),0) -> 0
A23: 20/04/2025 | B23: الاثنين | C23: EMP-001 | D23: =VLOOKUP(C23,Employees!A:J,2,0) -> احمد خالد | E23: 0.5 | F23: 0.91666667 | G23: حضور | H23: =E23 -> 0.5 | I23: =F23 -> 0.91666667 | J23: =IF(OR(H23="",G23="غياب",G23="إجازة أسبوعية"),0, IF(H23>=E23-TIME(0,20,0),0, IF(H23>=E23-TIME(0,30,0),30,(E23-H23)*1440))) -> 0 | K23: =(J23/60)*VLOOKUP(C23,Employees!A:J,10,0)*1.5 -> 0 | L23: =IF(OR(H23="",G23="غياب",G23="إجازة أسبوعية"),0, IF(H23<=E23+TIME(0,30,0),0, 30+((H23-(E23+TIME(0,30,0)))*1440))) -> 0 | M23: =(L23/60)*VLOOKUP(C23,Employees!A:J,10,0)*2 -> 0 | N23: =IF(OR(I23="",G23="غياب",G23="إجازة أسبوعية",I23<=F23),0, IF(MOD(I23-F23,1)<=TIME(0,25,0),0,MAX(0,(I23-F23)*1440))) -> 0 | O23: =(N23/60)*VLOOKUP(C23,Employees!A:J,10,0)*1.5 -> 0 | P23: =IF(G23="غياب",VLOOKUP(C23,Employees!$A$3:$J$36,9,FALSE()),0) -> 0
A24: 21/04/2025 | B24: الثلاثاء | C24: EMP-001 | D24: =VLOOKUP(C24,Employees!A:J,2,0) -> احمد خالد | E24: 0.5 | F24: 0.91666667 | G24: حضور | H24: =E24 -> 0.5 | I24: =F24 -> 0.91666667 | J24: =IF(OR(H24="",G24="غياب",G24="إجازة أسبوعية"),0, IF(H24>=E24-TIME(0,20,0),0, IF(H24>=E24-TIME(0,30,0),30,(E24-H24)*1440))) -> 0 | K24: =(J24/60)*VLOOKUP(C24,Employees!A:J,10,0)*1.5 -> 0 | L24: =IF(OR(H24="",G24="غياب",G24="إجازة أسبوعية"),0, IF(H24<=E24+TIME(0,30,0),0, 30+((H24-(E24+TIME(0,30,0)))*1440))) -> 0 | M24: =(L24/60)*VLOOKUP(C24,Employees!A:J,10,0)*2 -> 0 | N24: =IF(OR(I24="",G24="غياب",G24="إجازة أسبوعية",I24<=F24),0, IF(MOD(I24-F24,1)<=TIME(0,25,0),0,MAX(0,(I24-F24)*1440))) -> 0 | O24: =(N24/60)*VLOOKUP(C24,Employees!A:J,10,0)*1.5 -> 0 | P24: =IF(G24="غياب",VLOOKUP(C24,Employees!$A$3:$J$36,9,FALSE()),0) -> 0
A25: 22/04/2025 | B25: الاربعاء | C25: EMP-001 | D25: =VLOOKUP(C25,Employees!A:J,2,0) -> احمد خالد | E25: 0.5 | F25: 0.91666667 | G25: حضور | H25: =E25 -> 0.5 | I25: =F25 -> 0.91666667 | J25: =IF(OR(H25="",G25="غياب",G25="إجازة أسبوعية"),0, IF(H25>=E25-TIME(0,20,0),0, IF(H25>=E25-TIME(0,30,0),30,(E25-H25)*1440))) -> 0 | K25: =(J25/60)*VLOOKUP(C25,Employees!A:J,10,0)*1.5 -> 0 | L25: =IF(OR(H25="",G25="غياب",G25="إجازة أسبوعية"),0, IF(H25<=E25+TIME(0,30,0),0, 30+((H25-(E25+TIME(0,30,0)))*1440))) -> 0 | M25: =(L25/60)*VLOOKUP(C25,Employees!A:J,10,0)*2 -> 0 | N25: =IF(OR(I25="",G25="غياب",G25="إجازة أسبوعية",I25<=F25),0, IF(MOD(I25-F25,1)<=TIME(0,25,0),0,MAX(0,(I25-F25)*1440))) -> 0 | O25: =(N25/60)*VLOOKUP(C25,Employees!A:J,10,0)*1.5 -> 0 | P25: =IF(G25="غياب",VLOOKUP(C25,Employees!$A$3:$J$36,9,FALSE()),0) -> 0
A26: 23/04/2025 | B26: الخميس | C26: EMP-001 | D26: =VLOOKUP(C26,Employees!A:J,2,0) -> احمد خالد | E26: 0.5 | F26: 0.91666667 | G26: حضور | H26: =E26 -> 0.5 | I26: =F26 -> 0.91666667 | J26: =IF(OR(H26="",G26="غياب",G26="إجازة أسبوعية"),0, IF(H26>=E26-TIME(0,20,0),0, IF(H26>=E26-TIME(0,30,0),30,(E26-H26)*1440))) -> 0 | K26: =(J26/60)*VLOOKUP(C26,Employees!A:J,10,0)*1.5 -> 0 | L26: =IF(OR(H26="",G26="غياب",G26="إجازة أسبوعية"),0, IF(H26<=E26+TIME(0,30,0),0, 30+((H26-(E26+TIME(0,30,0)))*1440))) -> 0 | M26: =(L26/60)*VLOOKUP(C26,Employees!A:J,10,0)*2 -> 0 | N26: =IF(OR(I26="",G26="غياب",G26="إجازة أسبوعية",I26<=F26),0, IF(MOD(I26-F26,1)<=TIME(0,25,0),0,MAX(0,(I26-F26)*1440))) -> 0 | O26: =(N26/60)*VLOOKUP(C26,Employees!A:J,10,0)*1.5 -> 0 | P26: =IF(G26="غياب",VLOOKUP(C26,Employees!$A$3:$J$36,9,FALSE()),0) -> 0
A27: 24/04/2025 | B27: الجمعه | C27: EMP-001 | D27: =VLOOKUP(C27,Employees!A:J,2,0) -> احمد خالد | E27: 0.45833333 | F27: 0.875 | G27: حضور | H27: =E27 -> 0.45833333 | I27: =F27 -> 0.875 | J27: =IF(OR(H27="",G27="غياب",G27="إجازة أسبوعية"),0, IF(H27>=E27-TIME(0,20,0),0, IF(H27>=E27-TIME(0,30,0),30,(E27-H27)*1440))) -> 0 | K27: =(J27/60)*VLOOKUP(C27,Employees!A:J,10,0)*1.5 -> 0 | L27: =IF(OR(H27="",G27="غياب",G27="إجازة أسبوعية"),0, IF(H27<=E27+TIME(0,30,0),0, 30+((H27-(E27+TIME(0,30,0)))*1440))) -> 0 | M27: =(L27/60)*VLOOKUP(C27,Employees!A:J,10,0)*2 -> 0 | N27: =IF(OR(I27="",G27="غياب",G27="إجازة أسبوعية",I27<=F27),0, IF(MOD(I27-F27,1)<=TIME(0,25,0),0,MAX(0,(I27-F27)*1440))) -> 0 | O27: =(N27/60)*VLOOKUP(C27,Employees!A:J,10,0)*1.5 -> 0 | P27: =IF(G27="غياب",VLOOKUP(C27,Employees!$A$3:$J$36,9,FALSE()),0) -> 0
A28: 25/04/2025 | B28: السبت | C28: EMP-001 | D28: =VLOOKUP(C28,Employees!A:J,2,0) -> احمد خالد | E28: 0.45833333 | F28: 0.875 | G28: حضور | H28: =E28 -> 0.45833333 | I28: =F28 -> 0.875 | J28: =IF(OR(H28="",G28="غياب",G28="إجازة أسبوعية"),0, IF(H28>=E28-TIME(0,20,0),0, IF(H28>=E28-TIME(0,30,0),30,(E28-H28)*1440))) -> 0 | K28: =(J28/60)*VLOOKUP(C28,Employees!A:J,10,0)*1.5 -> 0 | L28: =IF(OR(H28="",G28="غياب",G28="إجازة أسبوعية"),0, IF(H28<=E28+TIME(0,30,0),0, 30+((H28-(E28+TIME(0,30,0)))*1440))) -> 0 | M28: =(L28/60)*VLOOKUP(C28,Employees!A:J,10,0)*2 -> 0 | N28: =IF(OR(I28="",G28="غياب",G28="إجازة أسبوعية",I28<=F28),0, IF(MOD(I28-F28,1)<=TIME(0,25,0),0,MAX(0,(I28-F28)*1440))) -> 0 | O28: =(N28/60)*VLOOKUP(C28,Employees!A:J,10,0)*1.5 -> 0 | P28: =IF(G28="غياب",VLOOKUP(C28,Employees!$A$3:$J$36,9,FALSE()),0) -> 0
A29: 26/04/2025 | B29: الاحد | C29: EMP-001 | D29: =VLOOKUP(C29,Employees!A:J,2,0) -> احمد خالد | E29: _ | F29: _ | G29: اجازة اسبوعية | H29: _ | I29: _ | J29: _ | K29: _ | L29: _ | M29: _ | N29: _ | O29: _ | P29: =IF(G29="غياب",VLOOKUP(C29,Employees!$A$3:$J$36,9,FALSE()),0) -> 0
A30: 27/04/2025 | B30: الاثنين | C30: EMP-001 | D30: =VLOOKUP(C30,Employees!A:J,2,0) -> احمد خالد | E30: 0.45833333 | F30: 0.875 | G30: حضور | H30: =E30 -> 0.45833333 | I30: =F30 -> 0.875 | J30: =IF(OR(H30="",G30="غياب",G30="إجازة أسبوعية"),0, IF(H30>=E30-TIME(0,20,0),0, IF(H30>=E30-TIME(0,30,0),30,(E30-H30)*1440))) -> 0 | K30: =(J30/60)*VLOOKUP(C30,Employees!A:J,10,0)*1.5 -> 0 | L30: =IF(OR(H30="",G30="غياب",G30="إجازة أسبوعية"),0, IF(H30<=E30+TIME(0,30,0),0, 30+((H30-(E30+TIME(0,30,0)))*1440))) -> 0 | M30: =(L30/60)*VLOOKUP(C30,Employees!A:J,10,0)*2 -> 0 | N30: =IF(OR(I30="",G30="غياب",G30="إجازة أسبوعية",I30<=F30),0, IF(MOD(I30-F30,1)<=TIME(0,25,0),0,MAX(0,(I30-F30)*1440))) -> 0 | O30: =(N30/60)*VLOOKUP(C30,Employees!A:J,10,0)*1.5 -> 0 | P30: =IF(G30="غياب",VLOOKUP(C30,Employees!$A$3:$J$36,9,FALSE()),0) -> 0
A31: 28/04/2025 | B31: الثلاثاء | C31: EMP-001 | D31: =VLOOKUP(C31,Employees!A:J,2,0) -> احمد خالد | E31: 0.45833333 | F31: 0.875 | G31: حضور | H31: =E31 -> 0.45833333 | I31: =F31 -> 0.875 | J31: =IF(OR(H31="",G31="غياب",G31="إجازة أسبوعية"),0, IF(H31>=E31-TIME(0,20,0),0, IF(H31>=E31-TIME(0,30,0),30,(E31-H31)*1440))) -> 0 | K31: =(J31/60)*VLOOKUP(C31,Employees!A:J,10,0)*1.5 -> 0 | L31: =IF(OR(H31="",G31="غياب",G31="إجازة أسبوعية"),0, IF(H31<=E31+TIME(0,30,0),0, 30+((H31-(E31+TIME(0,30,0)))*1440))) -> 0 | M31: =(L31/60)*VLOOKUP(C31,Employees!A:J,10,0)*2 -> 0 | N31: =IF(OR(I31="",G31="غياب",G31="إجازة أسبوعية",I31<=F31),0, IF(MOD(I31-F31,1)<=TIME(0,25,0),0,MAX(0,(I31-F31)*1440))) -> 0 | O31: =(N31/60)*VLOOKUP(C31,Employees!A:J,10,0)*1.5 -> 0 | P31: =IF(G31="غياب",VLOOKUP(C31,Employees!$A$3:$J$36,9,FALSE()),0) -> 0
A32: 29/04/2025 | B32: الاربعاء | C32: EMP-001 | D32: =VLOOKUP(C32,Employees!A:J,2,0) -> احمد خالد | E32: 0.45833333 | F32: 0.875 | G32: حضور | H32: =E32 -> 0.45833333 | I32: =F32 -> 0.875 | J32: =IF(OR(H32="",G32="غياب",G32="إجازة أسبوعية"),0, IF(H32>=E32-TIME(0,20,0),0, IF(H32>=E32-TIME(0,30,0),30,(E32-H32)*1440))) -> 0 | K32: =(J32/60)*VLOOKUP(C32,Employees!A:J,10,0)*1.5 -> 0 | L32: =IF(OR(H32="",G32="غياب",G32="إجازة أسبوعية"),0, IF(H32<=E32+TIME(0,30,0),0, 30+((H32-(E32+TIME(0,30,0)))*1440))) -> 0 | M32: =(L32/60)*VLOOKUP(C32,Employees!A:J,10,0)*2 -> 0 | N32: =IF(OR(I32="",G32="غياب",G32="إجازة أسبوعية",I32<=F32),0, IF(MOD(I32-F32,1)<=TIME(0,25,0),0,MAX(0,(I32-F32)*1440))) -> 0 | O32: =(N32/60)*VLOOKUP(C32,Employees!A:J,10,0)*1.5 -> 0 | P32: =IF(G32="غياب",VLOOKUP(C32,Employees!$A$3:$J$36,9,FALSE()),0) -> 0
A33: 30/04/2025 | B33: الخميس | C33: EMP-001 | D33: =VLOOKUP(C33,Employees!A:J,2,0) -> احمد خالد | E33: 0.45833333 | F33: 0.875 | G33: حضور | H33: =E33 -> 0.45833333 | I33: =F33 -> 0.875 | J33: =IF(OR(H33="",G33="غياب",G33="إجازة أسبوعية"),0, IF(H33>=E33-TIME(0,20,0),0, IF(H33>=E33-TIME(0,30,0),30,(E33-H33)*1440))) -> 0 | K33: =(J33/60)*VLOOKUP(C33,Employees!A:J,10,0)*1.5 -> 0 | L33: =IF(OR(H33="",G33="غياب",G33="إجازة أسبوعية"),0, IF(H33<=E33+TIME(0,30,0),0, 30+((H33-(E33+TIME(0,30,0)))*1440))) -> 0 | M33: =(L33/60)*VLOOKUP(C33,Employees!A:J,10,0)*2 -> 0 | N33: =IF(OR(I33="",G33="غياب",G33="إجازة أسبوعية",I33<=F33),0, IF(MOD(I33-F33,1)<=TIME(0,25,0),0,MAX(0,(I33-F33)*1440))) -> 0 | O33: =(N33/60)*VLOOKUP(C33,Employees!A:J,10,0)*1.5 -> 0 | P33: =IF(G33="غياب",VLOOKUP(C33,Employees!$A$3:$J$36,9,FALSE()),0) -> 0
A34: 01/04/2025 | B34: الاربعاء | C34: EMP-002 | D34: =VLOOKUP(C34,Employees!A:J,2,0) -> هشام عادل | E34: 0.39791667 | F34: 0.75 | G34: حضور | H34: =E34 -> 0.39791667 | I34: =F34 -> 0.75 | J34: =IF(OR(H34="",G34="غياب",G34="إجازة أسبوعية"),0, IF(H34>=E34-TIME(0,20,0),0, IF(H34>=E34-TIME(0,30,0),30,(E34-H34)*1440))) -> 0 | K34: =(J34/60)*VLOOKUP(C34,Employees!A:J,10,0)*1.5 -> 0 | L34: =IF(OR(H34="",G34="غياب",G34="إجازة أسبوعية"),0, IF(H34<=E34+TIME(0,30,0),0, 30+((H34-(E34+TIME(0,30,0)))*1440))) -> 0 | M34: =(L34/60)*VLOOKUP(C34,Employees!A:J,10,0)*2 -> 0 | N34: =IF(OR(I34="",G34="غياب",G34="إجازة أسبوعية",I34<=F34),0, IF(MOD(I34-F34,1)<=TIME(0,25,0),0,MAX(0,(I34-F34)*1440))) -> 0 | O34: =(N34/60)*VLOOKUP(C34,Employees!A:J,10,0)*1.5 -> 0 | P34: =IF(G34="غياب",VLOOKUP(C34,Employees!$A$3:$J$36,9,FALSE()),0) -> 0
A35: 02/04/2025 | B35: الخميس | C35: EMP-002 | D35: =VLOOKUP(C35,Employees!A:J,2,0) -> هشام عادل | E35: 0.39166667 | F35: 0.75 | G35: حضور | H35: =E35 -> 0.39166667 | I35: =F35 -> 0.75 | J35: =IF(OR(H35="",G35="غياب",G35="إجازة أسبوعية"),0, IF(H35>=E35-TIME(0,20,0),0, IF(H35>=E35-TIME(0,30,0),30,(E35-H35)*1440))) -> 0 | K35: =(J35/60)*VLOOKUP(C35,Employees!A:J,10,0)*1.5 -> 0 | L35: =IF(OR(H35="",G35="غياب",G35="إجازة أسبوعية"),0, IF(H35<=E35+TIME(0,30,0),0, 30+((H35-(E35+TIME(0,30,0)))*1440))) -> 0 | M35: =(L35/60)*VLOOKUP(C35,Employees!A:J,10,0)*2 -> 0 | N35: =IF(OR(I35="",G35="غياب",G35="إجازة أسبوعية",I35<=F35),0, IF(MOD(I35-F35,1)<=TIME(0,25,0),0,MAX(0,(I35-F35)*1440))) -> 0 | O35: =(N35/60)*VLOOKUP(C35,Employees!A:J,10,0)*1.5 -> 0 | P35: =IF(G35="غياب",VLOOKUP(C35,Employees!$A$3:$J$36,9,FALSE()),0) -> 0
A36: 03/04/2025 | B36: الجمعه | C36: EMP-002 | D36: =VLOOKUP(C36,Employees!A:J,2,0) -> هشام عادل | E36: 0.39583333 | F36: 0.75 | G36: حضور | H36: =E36 -> 0.39583333 | I36: =F36 -> 0.75 | J36: =IF(OR(H36="",G36="غياب",G36="إجازة أسبوعية"),0, IF(H36>=E36-TIME(0,20,0),0, IF(H36>=E36-TIME(0,30,0),30,(E36-H36)*1440))) -> 0 | K36: =(J36/60)*VLOOKUP(C36,Employees!A:J,10,0)*1.5 -> 0 | L36: =IF(OR(H36="",G36="غياب",G36="إجازة أسبوعية"),0, IF(H36<=E36+TIME(0,30,0),0, 30+((H36-(E36+TIME(0,30,0)))*1440))) -> 0 | M36: =(L36/60)*VLOOKUP(C36,Employees!A:J,10,0)*2 -> 0 | N36: =IF(OR(I36="",G36="غياب",G36="إجازة أسبوعية",I36<=F36),0, IF(MOD(I36-F36,1)<=TIME(0,25,0),0,MAX(0,(I36-F36)*1440))) -> 0 | O36: =(N36/60)*VLOOKUP(C36,Employees!A:J,10,0)*1.5 -> 0 | P36: =IF(G36="غياب",VLOOKUP(C36,Employees!$A$3:$J$36,9,FALSE()),0) -> 0
A37: 04/04/2025 | B37: السبت | C37: EMP-002 | D37: =VLOOKUP(C37,Employees!A:J,2,0) -> هشام عادل | E37: 0.38958333 | F37: 0.75 | G37: حضور | H37: =E37 -> 0.38958333 | I37: =F37 -> 0.75 | J37: =IF(OR(H37="",G37="غياب",G37="إجازة أسبوعية"),0, IF(H37>=E37-TIME(0,20,0),0, IF(H37>=E37-TIME(0,30,0),30,(E37-H37)*1440))) -> 0 | K37: =(J37/60)*VLOOKUP(C37,Employees!A:J,10,0)*1.5 -> 0 | L37: =IF(OR(H37="",G37="غياب",G37="إجازة أسبوعية"),0, IF(H37<=E37+TIME(0,30,0),0, 30+((H37-(E37+TIME(0,30,0)))*1440))) -> 0 | M37: =(L37/60)*VLOOKUP(C37,Employees!A:J,10,0)*2 -> 0 | N37: =IF(OR(I37="",G37="غياب",G37="إجازة أسبوعية",I37<=F37),0, IF(MOD(I37-F37,1)<=TIME(0,25,0),0,MAX(0,(I37-F37)*1440))) -> 0 | O37: =(N37/60)*VLOOKUP(C37,Employees!A:J,10,0)*1.5 -> 0 | P37: =IF(G37="غياب",VLOOKUP(C37,Employees!$A$3:$J$36,9,FALSE()),0) -> 0
A38: 05/04/2025 | B38: الاحد | C38: EMP-002 | D38: =VLOOKUP(C38,Employees!A:J,2,0) -> هشام عادل | E38: _ | F38: _ | G38: اجازة اسبوعية | H38: _ | I38: _ | J38: _ | K38: _ | L38: _ | M38: _ | N38: _ | O38: _ | P38: =IF(G38="غياب",VLOOKUP(C38,Employees!$A$3:$J$36,9,FALSE()),0) -> 0
A39: 06/04/2025 | B39: الاثنين | C39: EMP-002 | D39: =VLOOKUP(C39,Employees!A:J,2,0) -> هشام عادل | E39: 0.40347222 | F39: 0.75 | G39: حضور | H39: =E39 -> 0.40347222 | I39: =F39 -> 0.75 | J39: =IF(OR(H39="",G39="غياب",G39="إجازة أسبوعية"),0, IF(H39>=E39-TIME(0,20,0),0, IF(H39>=E39-TIME(0,30,0),30,(E39-H39)*1440))) -> 0 | K39: =(J39/60)*VLOOKUP(C39,Employees!A:J,10,0)*1.5 -> 0 | L39: =IF(OR(H39="",G39="غياب",G39="إجازة أسبوعية"),0, IF(H39<=E39+TIME(0,30,0),0, 30+((H39-(E39+TIME(0,30,0)))*1440))) -> 0 | M39: =(L39/60)*VLOOKUP(C39,Employees!A:J,10,0)*2 -> 0 | N39: =IF(OR(I39="",G39="غياب",G39="إجازة أسبوعية",I39<=F39),0, IF(MOD(I39-F39,1)<=TIME(0,25,0),0,MAX(0,(I39-F39)*1440))) -> 0 | O39: =(N39/60)*VLOOKUP(C39,Employees!A:J,10,0)*1.5 -> 0 | P39: =IF(G39="غياب",VLOOKUP(C39,Employees!$A$3:$J$36,9,FALSE()),0) -> 0
A40: 07/04/2025 | B40: الثلاثاء | C40: EMP-002 | D40: =VLOOKUP(C40,Employees!A:J,2,0) -> هشام عادل | E40: 0.39652778 | F40: 0.75 | G40: حضور | H40: =E40 -> 0.39652778 | I40: =F40 -> 0.75 | J40: =IF(OR(H40="",G40="غياب",G40="إجازة أسبوعية"),0, IF(H40>=E40-TIME(0,20,0),0, IF(H40>=E40-TIME(0,30,0),30,(E40-H40)*1440))) -> 0 | K40: =(J40/60)*VLOOKUP(C40,Employees!A:J,10,0)*1.5 -> 0 | L40: =IF(OR(H40="",G40="غياب",G40="إجازة أسبوعية"),0, IF(H40<=E40+TIME(0,30,0),0, 30+((H40-(E40+TIME(0,30,0)))*1440))) -> 0 | M40: =(L40/60)*VLOOKUP(C40,Employees!A:J,10,0)*2 -> 0 | N40: =IF(OR(I40="",G40="غياب",G40="إجازة أسبوعية",I40<=F40),0, IF(MOD(I40-F40,1)<=TIME(0,25,0),0,MAX(0,(I40-F40)*1440))) -> 0 | O40: =(N40/60)*VLOOKUP(C40,Employees!A:J,10,0)*1.5 -> 0 | P40: =IF(G40="غياب",VLOOKUP(C40,Employees!$A$3:$J$36,9,FALSE()),0) -> 0
...

Sheet Advances & Deductions
A1: السلف والخصومات - أبريل 2025
A2: كود الموظف | B2: اسم الموظف | C2: الوظيفة | D2: سلف اول اسبوع | E2: سلف ثانى اسبوع | F2: سلف ثالث اسبوع | G2: سلف رابع اسبوع | H2: اجمالى السلف | I2: خصومات أخرى | J2: NOTES
A3: EMP-001 | B3: احمد خالد | C3: مدير مبيعات | D3: 0 | E3: 2000 | F3: 2500 | G3: 2500 | H3: =G3+F3+E3+D3 -> 7000 | I3: 0
A4: EMP-002 | B4: هشام عادل | C4: مدير مبيعات | D4: 700 | E4: 5700 | F4: 800 | G4: 500 | H4: =G4+F4+E4+D4 -> 7700 | I4: 0
A5: EMP-003 | B5: احمد الشاذلى | C5: مبيعات | D5: 0 | E5: 4000 | F5: 0 | G5: 0 | H5: =G5+F5+E5+D5 -> 4000 | I5: 0
A6: EMP-004 | B6: يوسف احمد | C6: مبيعات | D6: 1300 | E6: 1300 | F6: 1300 | G6: 1300 | H6: =G6+F6+E6+D6 -> 5200 | I6: 0
A7: EMP-005 | B7: محمد السيد | C7: مبيعات | D7: 1200 | E7: 1500 | F7: 1500 | G7: 1300 | H7: =G7+F7+E7+D7 -> 5500 | I7: 0
A8: EMP-006 | B8: يحي طارق | C8: مبيعات | D8: 1300 | E8: 1300 | F8: 1300 | G8: 1300 | H8: =G8+F8+E8+D8 -> 5200 | I8: 0
A9: EMP-007 | B9: عابدين محمد | C9: مبيعات | D9: 1300 | E9: 1300 | F9: 1600 | G9: 1300 | H9: =G9+F9+E9+D9 -> 5500 | I9: 0
A10: EMP-008 | B10: احمد رمصان | C10: مبيعات | D10: 800 | E10: 2500 | F10: 700 | G10: 1000 | H10: =G10+F10+E10+D10 -> 5000 | I10: 0
A11: EMP-009 | B11: هشام اشرف | C11: مبيعات | D11: 1100 | E11: 1100 | F11: 1100 | G11: 1500 | H11: =G11+F11+E11+D11 -> 4800 | I11: 0
A12: EMP-010 | B12: محمود اسماعيل | C12: مبيعات | D12: 1000 | E12: 0 | F12: 0 | G12: 0 | H12: =G12+F12+E12+D12 -> 1000 | I12: 0
A13: EMP-011 | B13: ابراهيم خليفة | C13: مبيعات | D13: 500 | E13: 5000 | F13: 1000 | G13: 1000 | H13: =G13+F13+E13+D13 -> 7500 | I13: 0
A14: EMP-012 | B14: طارق سعد | C14: مبيعات | D14: 0 | E14: 0 | F14: 0 | G14: 0 | H14: =G14+F14+E14+D14 -> 0 | I14: 0
... A24: EMP-022 | B24: مصطفى شريف | C24: اداره | D24: 1300 | E24: 1300 | F24: 1300 | G24: 0 | H24: =G24+F24+E24+D24 -> 3900 | I24: 0
A25: EMP-023 | B25: احمد اشرف | C25: اداره | E25: 1300 | G25: 850 | H25: =G25+F25+E25+D25 -> 2150 | I25: 4000 | J25: بمعرفة الحاج ياسر
A26: EMP-024 | B26: منى ناصر | C26: تسويق | D26: 1200 | E26: 1200 | F26: 1200 | G26: 1200 | H26: =G26+F26+E26+D26 -> 4800 | I26: 1400 | J26: عجز نقدية هارون المالكي
A27: EMP-025 | B27: مريم فتح الله | C27: تسويق | D27: 0 | E27: 0 | F27: 0 | G27: 0 | H27: =G27+F27+E27+D27 -> 0 | I27: 0
A28: EMP-026 | B28: ساميه محمد | C28: تسويق | E28: 1200 | F28: 1200 | G28: 0 | H28: =G28+F28+E28+D28 -> 2400 | I28: 0
A29: EMP-027 | B29: غادة منير | C29: تسويق | D29: 1500 | E29: 500 | F29: 500 | H29: =G29+F29+E29+D29 -> 2500 | I29: 0
A30: EMP-028 | B30: هيام عبدالرحيم | C30: تسويق | D30: 0 | E30: 0 | F30: 0 | G30: 0 | H30: =G30+F30+E30+D30 -> 0 | I30: 0
A31: EMP-029 | B31: يونس خالد | C31: تسويق | D31: 950 | E31: 950 | F31: 950 | G31: 950 | H31: =G31+F31+E31+D31 -> 3800 | I31: 0
A32: EMP-030 | B32: محمد طارق | C32: تسويق | D32: 0 | E32: 0 | F32: 0 | G32: 0 | H32: =G32+F32+E32+D32 -> 0 | I32: 0
A33: EMP-031 | B33: انس انور | C33: اداره | E33: 0 | F33: 1300 | G33: 1300 | H33: =G33+F33+E33+D33 -> 2600 | I33: 0
A34: EMP-032 | B34: مراون عادل | C34: اداره | D34: 1000 | E34: 0 | F34: 0 | G34: 0 | H34: =G34+F34+E34+D34 -> 1000 | I34: 0
A35: EMP-033 | B35: سعد محمد | C35: اداره | D35: 0 | E35: 0 | F35: 0 | G35: 0 | H35: =G35+F35+E35+D35 -> 0 | I35: 0
A36: الإجمالي | D36: =SUM(D3:D35) -> 23050 | E36: =SUM(E3:E35) -> 39650 | F36: =SUM(F3:F35) -> 25550 | G36: =SUM(G3:G35) -> 23500 | H36: =SUM(H3:H35) -> 111750 | I36: =SUM(I3:I35) -> 5400

Sheet Payroll Summary
A1: ملخص المرتبات - أبريل 2025
A2: كود الموظف | B2: اسم الموظف | C2: الوظيفة | D2: المرتب الأساسي | E2: خصم الغياب | F2: خصم التأخير | G2: إجمالي الأوفر تايم | H2: اجمالى الحضور المبكر | I2: السلف | J2: الخصومات الأخرى | K2: صافي المرتب
A3: EMP-001 | B3: احمد خالد | C3: مدير مبيعات | D3: =VLOOKUP(A3,Employees!A:J,4,0) -> 10000 | E3: =SUMIF(Attendance!$C$4:$C$993,A3,Attendance!$P$4:$P$993) -> 0 | F3: =SUMIF(Attendance!$C$4:$C$993,A3,Attendance!$M$4:$M$993) -> 0 | G3: =SUMIF(Attendance!$C$4:$C$993,A3,Attendance!$O$4:$O$993) -> 0 | H3: =SUMIF(Attendance!$C$4:$C$993,'Payroll Summary'!A3,Attendance!$K$4:$K$993) -> 0 | I3: ='Advances & Deductions'!H3 -> 7000 | J3: ='Advances & Deductions'!I3 -> 0 | K3: =D3-E3-F3-I3-J3+G3+H3 -> 3000
A4: EMP-002 | B4: هشام عادل | C4: مدير مبيعات | D4: =VLOOKUP(A4,Employees!A:J,4,0) -> 9000 | E4: =SUMIF(Attendance!$C$4:$C$993,A4,Attendance!$P$4:$P$993) -> 0 | F4: =SUMIF(Attendance!$C$4:$C$993,A4,Attendance!$M$4:$M$993) -> 0 | G4: =SUMIF(Attendance!$C$4:$C$993,A4,Attendance!$O$4:$O$993) -> 0 | H4: =SUMIF(Attendance!$C$4:$C$993,'Payroll Summary'!A4,Attendance!$K$4:$K$993) -> 0 | I4: ='Advances & Deductions'!H4 -> 7700 | J4: ='Advances & Deductions'!I4 -> 0 | K4: =D4-E4-F4-I4-J4+G4+H4 -> 1300
A5: EMP-003 | B5: احمد الشاذلى | C5: مبيعات | D5: =VLOOKUP(A5,Employees!A:J,4,0) -> 7000 | E5: =SUMIF(Attendance!$C$4:$C$993,A5,Attendance!$P$4:$P$993) -> 1037.037 | F5: =SUMIF(Attendance!$C$4:$C$993,A5,Attendance!$M$4:$M$993) -> 208.36763 | G5: =SUMIF(Attendance!$C$4:$C$993,A5,Attendance!$O$4:$O$993) -> 67.695473 | H5: =SUMIF(Attendance!$C$4:$C$993,'Payroll Summary'!A5,Attendance!$K$4:$K$993) -> 0 | I5: ='Advances & Deductions'!H5 -> 4000 | J5: ='Advances & Deductions'!I5 -> 0 | K5: =D5-E5-F5-I5-J5+G5+H5 -> 1822.2908
A6: EMP-004 | B6: يوسف احمد | C6: مبيعات | D6: =VLOOKUP(A6,Employees!A:J,4,0) -> 7000 | E6: =SUMIF(Attendance!$C$4:$C$993,A6,Attendance!$P$4:$P$993) -> 0 | F6: =SUMIF(Attendance!$C$4:$C$993,A6,Attendance!$M$4:$M$993) -> 75.617284 | G6: =SUMIF(Attendance!$C$4:$C$993,A6,Attendance!$O$4:$O$993) -> 104.78395 | H6: =SUMIF(Attendance!$C$4:$C$993,'Payroll Summary'!A6,Attendance!$K$4:$K$993) -> 0 | I6: ='Advances & Deductions'!H6 -> 5200 | J6: ='Advances & Deductions'!I6 -> 0 | K6: =D6-E6-F6-I6-J6+G6+H6 -> 1829.1667
A7: EMP-005 | B7: محمد السيد | C7: مبيعات | D7: =VLOOKUP(A7,Employees!A:J,4,0) -> 7000 | E7: =SUMIF(Attendance!$C$4:$C$993,A7,Attendance!$P$4:$P$993) -> 259.25926 | F7: =SUMIF(Attendance!$C$4:$C$993,A7,Attendance!$M$4:$M$993) -> 390.32922 | G7: =SUMIF(Attendance!$C$4:$C$993,A7,Attendance!$O$4:$O$993) -> 53.472222 | H7: =SUMIF(Attendance!$C$4:$C$993,'Payroll Summary'!A7,Attendance!$K$4:$K$993) -> 0 | I7: ='Advances & Deductions'!H7 -> 5500 | J7: ='Advances & Deductions'!I7 -> 0 | K7: =D7-E7-F7-I7-J7+G7+H7 -> 903.88374
A8: EMP-006 | B8: يحي طارق | C8: مبيعات | D8: =VLOOKUP(A8,Employees!A:J,4,0) -> 7000 | E8: =SUMIF(Attendance!$C$4:$C$993,A8,Attendance!$P$4:$P$993) -> 777.77778 | F8: =SUMIF(Attendance!$C$4:$C$993,A8,Attendance!$M$4:$M$993) -> 1814.0947 | G8: =SUMIF(Attendance!$C$4:$C$993,A8,Attendance!$O$4:$O$993) -> 242.51543 | H8: =SUMIF(Attendance!$C$4:$C$993,'Payroll Summary'!A8,Attendance!$K$4:$K$993) -> 0 | I8: ='Advances & Deductions'!H8 -> 5200 | J8: ='Advances & Deductions'!I8 -> 0 | K8: =D8-E8-F8-I8-J8+G8+H8 -> -549.357
A9: EMP-007 | B9: عابدين محمد | C9: مبيعات | D9: =VLOOKUP(A9,Employees!A:J,4,0) -> 7000 | E9: =SUMIF(Attendance!$C$4:$C$993,A9,Attendance!$P$4:$P$993) -> 1037.037 | F9: =SUMIF(Attendance!$C$4:$C$993,A9,Attendance!$M$4:$M$993) -> 2008.5391 | G9: =SUMIF(Attendance!$C$4:$C$993,A9,Attendance!$O$4:$O$993) -> 126.38889 | H9: =SUMIF(Attendance!$C$4:$C$993,'Payroll Summary'!A9,Attendance!$K$4:$K$993) -> 0 | I9: ='Advances & Deductions'!H9 -> 5500 | J9: ='Advances & Deductions'!I9 -> 0 | K9: =D9-E9-F9-I9-J9+G9+H9 -> -1419.1872
A10: EMP-008 | B10: احمد رمصان | C10: مبيعات | D10: =VLOOKUP(A10,Employees!A:J,4,0) -> 7000 | E10: =SUMIF(Attendance!$C$4:$C$993,A10,Attendance!$P$4:$P$993) -> 0 | F10: =SUMIF(Attendance!$C$4:$C$993,A10,Attendance!$M$4:$M$993) -> 0 | G10: =SUMIF(Attendance!$C$4:$C$993,A10,Attendance!$O$4:$O$993) -> 64.814815 | H10: =SUMIF(Attendance!$C$4:$C$993,'Payroll Summary'!A10,Attendance!$K$4:$K$993) -> 0 | I10: ='Advances & Deductions'!H10 -> 5000 | J10: ='Advances & Deductions'!I10 -> 0 | K10: =D10-E10-F10-I10-J10+G10+H10 -> 2064.8148
A11: EMP-009 | B11: هشام اشرف | C11: مبيعات | D11: =VLOOKUP(A11,Employees!A:J,4,0) -> 7000 | E11: =SUMIF(Attendance!$C$4:$C$993,A11,Attendance!$P$4:$P$993) -> 0 | F11: =SUMIF(Attendance!$C$4:$C$993,A11,Attendance!$M$4:$M$993) -> 93.621399 | G11: =SUMIF(Attendance!$C$4:$C$993,A11,Attendance!$O$4:$O$993) -> 156.6358 | H11: =SUMIF(Attendance!$C$4:$C$993,'Payroll Summary'!A11,Attendance!$K$4:$K$993) -> 0 | I11: ='Advances & Deductions'!H11 -> 4800 | J11: ='Advances & Deductions'!I11 -> 0 | K11: =D11-E11-F11-I11-J11+G11+H11 -> 2263.0144
A12: EMP-010 | B12: محمود اسماعيل | C12: مبيعات | D12: =VLOOKUP(A12,Employees!A:J,4,0) -> 7000 | E12: =SUMIF(Attendance!$C$4:$C$993,A12,Attendance!$P$4:$P$993) -> 259.25926 | F12: =SUMIF(Attendance!$C$4:$C$993,A12,Attendance!$M$4:$M$993) -> 0 | G12: =SUMIF(Attendance!$C$4:$C$993,A12,Attendance!$O$4:$O$993) -> 114.81481 | H12: =SUMIF(Attendance!$C$4:$C$993,'Payroll Summary'!A12,Attendance!$K$4:$K$993) -> 27.777778 | I12: ='Advances & Deductions'!H12 -> 1000 | J12: ='Advances & Deductions'!I12 -> 0 | K12: =D12-E12-F12-I12-J12+G12+H12 -> 5883.3333
A13: EMP-011 | B13: ابراهيم خليفة | C13: مبيعات | D13: =VLOOKUP(A13,Employees!A:J,4,0) -> 7000 | E13: =SUMIF(Attendance!$C$4:$C$993,A13,Attendance!$P$4:$P$993) -> 0 | F13: =SUMIF(Attendance!$C$4:$C$993,A13,Attendance!$M$4:$M$993) -> 0 | G13: =SUMIF(Attendance!$C$4:$C$993,A13,Attendance!$O$4:$O$993) -> 974.92284 | H13: =SUMIF(Attendance!$C$4:$C$993,'Payroll Summary'!A13,Attendance!$K$4:$K$993) -> 0 | I13: ='Advances & Deductions'!H13 -> 7500 | J13: ='Advances & Deductions'!I13 -> 0 | K13: =D13-E13-F13-I13-J13+G13+H13 -> 474.92284
A14: EMP-012 | B14: طارق سعد | C14: مبيعات | D14: =VLOOKUP(A14,Employees!A:J,4,0) -> 7000 | E14: =SUMIF(Attendance!$C$4:$C$993,A14,Attendance!$P$4:$P$993) -> 0 | F14: =SUMIF(Attendance!$C$4:$C$993,A14,Attendance!$M$4:$M$993) -> 0 | G14: =SUMIF(Attendance!$C$4:$C$993,A14,Attendance!$O$4:$O$993) -> 0 | H14: =SUMIF(Attendance!$C$4:$C$993,'Payroll Summary'!A14,Attendance!$K$4:$K$993) -> 0 | I14: ='Advances & Deductions'!H14 -> 0 | J14: ='Advances & Deductions'!I14 -> 0 | K14: =D14-E14-F14-I14-J14+G14+H14 -> 7000
... A35: EMP-033 | B35: سعد محمد | C35: اداره | D35: =VLOOKUP(A35,Employees!A:J,4,0) -> 12000 | E35: =SUMIF(Attendance!$C$4:$C$993,A35,Attendance!$P$4:$P$993) -> 0 | F35: =SUMIF(Attendance!$C$4:$C$993,A35,Attendance!$M$4:$M$993) -> 0 | G35: =SUMIF(Attendance!$C$4:$C$993,A35,Attendance!$O$4:$O$993) -> 0 | H35: =SUMIF(Attendance!$C$4:$C$993,'Payroll Summary'!A35,Attendance!$K$4:$K$993) -> 0 | I35: ='Advances & Deductions'!H35 -> 0 | J35: ='Advances & Deductions'!I35 -> 0 | K35: =D35-E35-F35-I35-J35+G35+H35 -> 12000
A36: الإجمالي الكلي | D36: =SUM(D3:D35) -> 294500 | E36: =SUM(E3:E35) -> 21185.185 | F36: =SUM(F3:F35) -> 7934.8903 | G36: =SUM(G3:G35) -> 7126.3735 | H36: =SUM(H3:H35) -> 409.72222 | I36: =SUM(I3:I35) -> 111750 | J36: =SUM(J3:J35) -> 5400 | K36: =SUM(K3:K35) -> 155766.02

Sheet Dashboard
A1: لوحة التحكم - ملخص المرتبات - أبريل 2025
A3: إجمالي الرواتب الأساسية | C3: إجمالي السلف | E3: إجمالي الخصومات الأخرى | G3: إجمالي خصم الغياب
A4: ='Payroll Summary'!D36 -> 294500 | C4: ='Payroll Summary'!I36 -> 111750 | E4: ='Payroll Summary'!J36 -> 5400 | G4: ='Payroll Summary'!E36 -> 21185.185
A6: إجمالي خصم التأخير | C6: إجمالي الأوفر تايم | E6: إجمالي صافي المرتبات | G6: اجمالى الحضور المبكر
A7: ='Payroll Summary'!F36 -> 7934.8903 | C7: ='Payroll Summary'!G36 -> 7126.3735 | E7: ='Payroll Summary'!K36 -> 155766.02 | G7: ='Payroll Summary'!H36 -> 409.72222
A10: ملخص تفصيلي لكل موظف
A11: الاسم | B11: الوظيفة | C11: المرتب | D11: الغياب | E11: التأخير | F11: الأوفر تايم | G11: السلف | H11: صافي المرتب
A12: ='Payroll Summary'!B3 -> احمد خالد | B12: ='Payroll Summary'!C3 -> مدير مبيعات | C12: ='Payroll Summary'!D3 -> 10000 | D12: ='Payroll Summary'!E3 -> 0 | E12: ='Payroll Summary'!F3 -> 0 | F12: ='Payroll Summary'!G3 -> 0 | G12: ='Payroll Summary'!I3 -> 7000 | H12: ='Payroll Summary'!K3 -> 3000
A13: ='Payroll Summary'!B4 -> هشام عادل | B13: ='Payroll Summary'!C4 -> مدير مبيعات | C13: ='Payroll Summary'!D4 -> 9000 | D13: ='Payroll Summary'!E4 -> 0 | E13: ='Payroll Summary'!F4 -> 0 | F13: ='Payroll Summary'!G4 -> 0 | G13: ='Payroll Summary'!I4 -> 7700 | H13: ='Payroll Summary'!K4 -> 1300
A14: ='Payroll Summary'!B5 -> احمد الشاذلى | B14: ='Payroll Summary'!C5 -> مبيعات | C14: ='Payroll Summary'!D5 -> 7000 | D14: ='Payroll Summary'!E5 -> 1037.037 | E14: ='Payroll Summary'!F5 -> 208.36763 | F14: ='Payroll Summary'!G5 -> 67.695473 | G14: ='Payroll Summary'!I5 -> 4000 | H14: ='Payroll Summary'!K5 -> 1822.2908
A15: ='Payroll Summary'!B6 -> يوسف احمد | B15: ='Payroll Summary'!C6 -> مبيعات | C15: ='Payroll Summary'!D6 -> 7000 | D15: ='Payroll Summary'!E6 -> 0 | E15: ='Payroll Summary'!F6 -> 75.617284 | F15: ='Payroll Summary'!G6 -> 104.78395 | G15: ='Payroll Summary'!I6 -> 5200 | H15: ='Payroll Summary'!K6 -> 1829.1667
A16: ='Payroll Summary'!B7 -> محمد السيد | B16: ='Payroll Summary'!C7 -> مبيعات | C16: ='Payroll Summary'!D7 -> 7000 | D16: ='Payroll Summary'!E7 -> 259.25926 | E16: ='Payroll Summary'!F7 -> 390.32922 | F16: ='Payroll Summary'!G7 -> 53.472222 | G16: ='Payroll Summary'!I7 -> 5500 | H16: ='Payroll Summary'!K7 -> 903.88374
A17: ='Payroll Summary'!B8 -> يحي طارق | B17: ='Payroll Summary'!C8 -> مبيعات | C17: ='Payroll Summary'!D8 -> 7000 | D17: ='Payroll Summary'!E8 -> 777.77778 | E17: ='Payroll Summary'!F8 -> 1814.0947 | F17: ='Payroll Summary'!G8 -> 242.51543 | G17: ='Payroll Summary'!I8 -> 5200 | H17: ='Payroll Summary'!K8 -> -549.357
A18: ='Payroll Summary'!B9 -> عابدين محمد | B18: ='Payroll Summary'!C9 -> مبيعات | C18: ='Payroll Summary'!D9 -> 7000 | D18: ='Payroll Summary'!E9 -> 1037.037 | E18: ='Payroll Summary'!F9 -> 2008.5391 | F18: ='Payroll Summary'!G9 -> 126.38889 | G18: ='Payroll Summary'!I9 -> 5500 | H18: ='Payroll Summary'!K9 -> -1419.1872
A19: ='Payroll Summary'!B10 -> احمد رمصان | B19: ='Payroll Summary'!C10 -> مبيعات | C19: ='Payroll Summary'!D10 -> 7000 | D19: ='Payroll Summary'!E10 -> 0 | E19: ='Payroll Summary'!F10 -> 0 | F19: ='Payroll Summary'!G10 -> 64.814815 | G19: ='Payroll Summary'!I10 -> 5000 | H19: ='Payroll Summary'!K10 -> 2064.8148
A20: ='Payroll Summary'!B11 -> هشام اشرف | B20: ='Payroll Summary'!C11 -> مبيعات | C20: ='Payroll Summary'!D11 -> 7000 | D20: ='Payroll Summary'!E11 -> 0 | E20: ='Payroll Summary'!F11 -> 93.621399 | F20: ='Payroll Summary'!G11 -> 156.6358 | G20: ='Payroll Summary'!I11 -> 4800 | H20: ='Payroll Summary'!K11 -> 2263.0144
A21: ='Payroll Summary'!B12 -> محمود اسماعيل | B21: ='Payroll Summary'!C12 -> مبيعات | C21: ='Payroll Summary'!D12 -> 7000 | D21: ='Payroll Summary'!E12 -> 259.25926 | E21: ='Payroll Summary'!F12 -> 0 | F21: ='Payroll Summary'!G12 -> 114.81481 | G21: ='Payroll Summary'!I12 -> 1000 | H21: ='Payroll Summary'!K12 -> 5883.3333
A22: ='Payroll Summary'!B13 -> ابراهيم خليفة | B22: ='Payroll Summary'!C13 -> مبيعات | C22: ='Payroll Summary'!D13 -> 7000 | D22: ='Payroll Summary'!E13 -> 0 | E22: ='Payroll Summary'!F13 -> 0 | F22: ='Payroll Summary'!G13 -> 974.92284 | G22: ='Payroll Summary'!I13 -> 7500 | H22: ='Payroll Summary'!K13 -> 474.92284
A23: ='Payroll Summary'!B14 -> طارق سعد | B23: ='Payroll Summary'!C14 -> مبيعات | C23: ='Payroll Summary'!D14 -> 7000 | D23: ='Payroll Summary'!E14 -> 0 | E23: ='Payroll Summary'!F14 -> 0 | F23: ='Payroll Summary'!G14 -> 0 | G23: ='Payroll Summary'!I14 -> 0 | H23: ='Payroll Summary'!K14 -> 7000
... A44: ='Payroll Summary'!B35 -> سعد محمد | B44: ='Payroll Summary'!C35 -> اداره | C44: ='Payroll Summary'!D35 -> 12000 | D44: ='Payroll Summary'!E35 -> 0 | E44: ='Payroll Summary'!F35 -> 0 | F44: ='Payroll Summary'!G35 -> 0 | G44: ='Payroll Summary'!I35 -> 0 | H44: ='Payroll Summary'!K35 -> 12000
